Traceback (most recent call last):
  File "/home/creator/Documents/Paradox/Github/Django/myshop/backend/backend/settings/setttings.py", line 26, in <module>
    SECRET_KEY = os.environ['SECRET_KEY']
                 ~~~~~~~~~~^^^^^^^^^^^^^^
  File "<frozen os>", line 679, in __getitem__
KeyError: 'SECRET_KEY'

The above exception was the direct cause of the following exception:

Traceback (most recent call last):
  File "/home/creator/Documents/Paradox/Github/Django/myshop/backend/manage.py", line 22, in <module>
    main()
  File "/home/creator/Documents/Paradox/Github/Django/myshop/backend/manage.py", line 18, in main
    execute_from_command_line(sys.argv)
  File "/home/creator/Documents/Paradox/Github/Django/myshop/venv/myshop/lib/python3.11/site-packages/django/core/management/__init__.py", line 446, in execute_from_command_line
    utility.execute()
  File "/home/creator/Documents/Paradox/Github/Django/myshop/venv/myshop/lib/python3.11/site-packages/django/core/management/__init__.py", line 386, in execute
    settings.INSTALLED_APPS
  File "/home/creator/Documents/Paradox/Github/Django/myshop/venv/myshop/lib/python3.11/site-packages/django/conf/__init__.py", line 92, in __getattr__
    self._setup(name)
  File "/home/creator/Documents/Paradox/Github/Django/myshop/venv/myshop/lib/python3.11/site-packages/django/conf/__init__.py", line 79, in _setup
    self._wrapped = Settings(settings_module)
                    ^^^^^^^^^^^^^^^^^^^^^^^^^
  File "/home/creator/Documents/Paradox/Github/Django/myshop/venv/myshop/lib/python3.11/site-packages/django/conf/__init__.py", line 190, in __init__
    mod = importlib.import_module(self.SETTINGS_MODULE)
          ^^^^^^^^^^^^^^^^^^^^^^^^^^^^^^^^^^^^^^^^^^^^^
  File "/home/creator/.pyenv/versions/3.11.1/lib/python3.11/importlib/__init__.py", line 126, in import_module
    return _bootstrap._gcd_import(name[level:], package, level)
           ^^^^^^^^^^^^^^^^^^^^^^^^^^^^^^^^^^^^^^^^^^^^^^^^^^^^
  File "<frozen importlib._bootstrap>", line 1206, in _gcd_import
  File "<frozen importlib._bootstrap>", line 1178, in _find_and_load
  File "<frozen importlib._bootstrap>", line 1149, in _find_and_load_unlocked
  File "<frozen importlib._bootstrap>", line 690, in _load_unlocked
  File "<frozen importlib._bootstrap_external>", line 940, in exec_module
  File "<frozen importlib._bootstrap>", line 241, in _call_with_frames_removed
  File "/home/creator/Documents/Paradox/Github/Django/myshop/backend/backend/settings/dev.py", line 1, in <module>
    from .setttings import * 
    ^^^^^^^^^^^^^^^^^^^^^^^^
  File "/home/creator/Documents/Paradox/Github/Django/myshop/backend/backend/settings/setttings.py", line 28, in <module>
    raise RuntimeError("Could not fiind a SECRET_KEY IN environment") from e
RuntimeError: Could not fiind a SECRET_KEY IN environment
Watching for file changes with StatReloader
Session data corrupted
[25/Mar/2023 15:03:56] "GET /admin/login/?next=/admin/ HTTP/1.1" 200 2218
[25/Mar/2023 15:03:56] "GET /static/admin/css/dark_mode.css HTTP/1.1" 304 0
[25/Mar/2023 15:03:56] "GET /static/admin/css/nav_sidebar.css HTTP/1.1" 304 0
[25/Mar/2023 15:03:56] "GET /static/admin/js/nav_sidebar.js HTTP/1.1" 304 0
[25/Mar/2023 15:03:56] "GET /static/admin/css/fonts.css HTTP/1.1" 304 0
[25/Mar/2023 15:03:56] "GET /static/admin/fonts/Roboto-Light-webfont.woff HTTP/1.1" 200 85692
[25/Mar/2023 15:03:56] "GET /static/admin/fonts/Roboto-Regular-webfont.woff HTTP/1.1" 200 85876
Performing system checks...

System check identified no issues (0 silenced).
March 25, 2023 - 15:03:49
Django version 4.1.7, using settings 'backend.settings.dev'
Starting development server at http://127.0.0.1:8000/
Quit the server with CONTROL-C.
Watching for file changes with StatReloader
Performing system checks...

System check identified no issues (0 silenced).
March 25, 2023 - 15:04:25
Django version 4.1.7, using settings 'backend.settings.dev'
Starting development server at http://127.0.0.1:8000/
Quit the server with CONTROL-C.
